Workbook
Name Slicer_Department: #N/A
Name Slicer_Employee_ID: #N/A
Name Slicer_Name: #N/A

Sheet  Formatting
A1: DAY-1 Formatting
A2: Employee ID | B2: Name | C2: Department | D2: Country | E2: Salary | F2: Date of Joining | G2: Performance Rating | H2: Gender | I2: Email
A3: EMP1000 | C3: Finance | E3: N/A | G3: 2 | H3: Unknown | I3: invalid_email
A4: EMP1001 | B4: Eve Adams | C4: HR | D4: Germany | E4: 54255 | F4: 42015 | G4: 1 | H4: Other | I4: user106@example.com
A5: EMP1002 | B5: Alice Brown | C5: Finance | D5: Germany | E5: 63184 | F5: 42022 | G5: 2 | I5: user176@example.com
A6: EMP1003 | B6: John Doe | C6: Sales | D6: USA | E6: 94406 | F6: 42029 | G6: 1 | H6: Male | I6: user168@example.com
A7: EMP1004 | B7: Jane Smith | C7: Sales | D7: Germany | E7: 64120 | F7: 42036 | G7: 1 | H7: Male | I7: user49@example.com
A8: EMP1005 | B8: Alice Brown | C8: IT | D8: India | E8: 78421 | F8: 42043 | G8: 2 | H8: Female | I8: user24@example.com
A9: EMP1006 | B9: Sam Wilson | C9: Sales | E9: 67721 | F9: 42050 | H9: Male | I9: user168@example.com
A10: EMP1007 | B10: Chris Lee | C10: Marketing | E10: 35364 | F10: 42057 | G10: 2 | H10: Other | I10: user26@example.com
A11: EMP1008 | B11: Alice Brown | C11: IT | D11: Germany | E11: 97881 | F11: 42064 | H11: Female | I11: user25@example.com
A12: EMP1009 | B12: Chris Lee | C12: HR | D12: UK | E12: 91846 | F12: 42071 | H12: Male | I12: user153@example.com
A13: EMP1010 | B13: Sam Wilson | C13: Finance | D13: UK | E13: 64247 | F13: 42078 | G13: 1 | H13: Female | I13: user18@example.com
A14: EMP1011 | B14: Sam Wilson | C14: IT | D14: USA | E14: 91180 | F14: 42085 | G14: 5 | H14: Male | I14: user1@example.com
A15: EMP1012 | B15: Bob Johnson | C15: Sales | E15: 96418 | F15: 42092 | G15: 5 | H15: Male | I15: user106@example.com
A16: EMP1013 | B16: Sam Wilson | D16: India | E16: 62158 | F16: 42099 | G16: 4 | I16: user180@example.com
A17: EMP1014 | B17: Jane Smith | C17: HR | E17: 59894 | F17: 42106 | G17: 2 | H17: Male | I17: user184@example.com
A18: EMP1015 | C18: IT | D18: India | E18: 92443 | F18: 42113 | G18: 3 | H18: Other | I18: user3@example.com
A19: EMP1016 | B19: Bob Johnson | D19: Germany | E19: 90271 | F19: 42120 | I19: user64@example.com
A20: EMP1017 | B20: Jane Smith | C20: Finance | D20: Australia | E20: 41341 | F20: 42127 | G20: 1 | H20: Other | I20: user38@example.com
A21: EMP1018 | B21: Alice Brown | C21: Finance | D21: UK | E21: 73602 | F21: 42134 | I21: user96@example.com
A22: EMP1019 | B22: Eve Adams | D22: India | E22: 67531 | F22: 42141 | G22: 5 | H22: Female | I22: user151@example.com
A23: EMP1020 | B23: Jane Smith | C23: HR | D23: USA | E23: N/A | F23: 42148 | G23: 2 | H23: Other | I23: user200@example.com
A24: EMP1021 | B24: Jane Smith | C24: HR | E24: 98922 | F24: 42155 | G24: 4 | I24: user77@example.com
A25: EMP1022 | B25: Eve Adams | C25: Finance | D25: India | E25: 38333 | F25: 42162 | G25: 5 | I25: user128@example.com
A26: EMP1023 | B26: Alice Brown | C26: Marketing | D26: UK | E26: 36515 | F26: 42169 | G26: 3 | H26: Male | I26: user149@example.com
A27: EMP1024 | B27: Sam Wilson | C27: Finance | E27: 91005 | F27: 42176 | G27: 1 | H27: Other | I27: user122@example.com
A28: EMP1025 | B28: Chris Lee | E28: 52272 | F28: 42183 | G28: 3 | I28: user41@example.com
A29: EMP1026 | B29: Eve Adams | C29: Sales | D29: Germany | E29: 76518 | F29: 42190 | G29: 2 | H29: Female | I29: user68@example.com
A30: EMP1027 | B30: Alice Brown | C30: IT | D30: UK | E30: 41448 | F30: 42197 | G30: 3 | H30: Other | I30: user103@example.com
A31: EMP1028 | B31: John Doe | C31: HR | D31: UK | E31: 49282 | F31: 42204 | G31: 2 | H31: Female | I31: user135@example.com
A32: EMP1029 | B32: Bob Johnson | C32: Marketing | D32: UK | E32: 92959 | F32: 42211 | G32: 5 | I32: user83@example.com
A33: EMP1030 | C33: Marketing | E33: 92259 | G33: 1 | H33: Unknown | I33: user109@example.com
A34: EMP1031 | B34: Eve Adams | C34: HR | D34: Germany | E34: 92299 | F34: 42225 | G34: 3 | H34: Male | I34: user143@example.com
A35: EMP1032 | B35: Sam Wilson | C35: HR | E35: 95586 | F35: 42232 | G35: 3 | H35: Other | I35: user190@example.com
A36: EMP1033 | B36: Chris Lee | D36: USA | E36: 95367 | F36: 42239 | H36: Male | I36: user136@example.com
A37: EMP1034 | B37: John Doe | C37: Sales | D37: Australia | E37: 79549 | F37: 42246 | G37: 3 | I37: user198@example.com
A38: EMP1035 | B38: Alice Brown | D38: UK | E38: 54463 | F38: 42253 | G38: 4 | H38: Male | I38: invalid_email
A39: EMP1036 | B39: Alice Brown | C39: IT | D39: USA | E39: 89781 | F39: 42260 | H39: Female | I39: user31@example.com
A40: EMP1037 | B40: Alice Brown | C40: HR | E40: 64796 | F40: 42267 | H40: Other | I40: user98@example.com
...

Sheet Cleaning
A1: DAY-2 Cleaning
A2: Employee ID | B2: Name | C2: Department | D2: Country | E2: Salary | F2: Date of Joining | G2: Performance Rating | H2: Gender | I2: Email
A3: EMP1000 | B3: Unknown | C3: Finance | D3: Unknown | E3: 66280.93 | F3: Unknown | G3: 2 | H3: Unknown | I3: Unknown
A4: EMP1001 | B4: Eve Adams | C4: HR | D4: Germany | E4: 54255 | F4: 42015 | G4: 1 | H4: Other | I4: user106@example.com
A5: EMP1002 | B5: Alice Brown | C5: Finance | D5: Germany | E5: 63184 | F5: 42022 | G5: 2 | H5: Unknown | I5: user176@example.com
A6: EMP1003 | B6: John Doe | C6: Sales | D6: USA | E6: 94406 | F6: 42029 | G6: 1 | H6: Male | I6: user168@example.com
A7: EMP1004 | B7: Jane Smith | C7: Sales | D7: Germany | E7: 64120 | F7: 42036 | G7: 1 | H7: Male | I7: user49@example.com
A8: EMP1005 | B8: Alice Brown | C8: IT | D8: India | E8: 78421 | F8: 42043 | G8: 2 | H8: Female | I8: user24@example.com
A9: EMP1006 | B9: Sam Wilson | C9: Sales | D9: Unknown | E9: 67721 | F9: 42050 | G9: 2.9411765 | H9: Male | I9: user168@example.com
A10: EMP1007 | B10: Chris Lee | C10: Marketing | D10: Unknown | E10: 35364 | F10: 42057 | G10: 2 | H10: Other | I10: user26@example.com
A11: EMP1008 | B11: Alice Brown | C11: IT | D11: Germany | E11: 97881 | F11: 42064 | G11: 2.9491525 | H11: Female | I11: user25@example.com
A12: EMP1009 | B12: Chris Lee | C12: HR | D12: UK | E12: 91846 | F12: 42071 | G12: 2.9491525 | H12: Male | I12: user153@example.com
A13: EMP1010 | B13: Sam Wilson | C13: Finance | D13: UK | E13: 64247 | F13: 42078 | G13: 1 | H13: Female | I13: user18@example.com
A14: EMP1011 | B14: Sam Wilson | C14: IT | D14: USA | E14: 91180 | F14: 42085 | G14: 5 | H14: Male | I14: user1@example.com
A15: EMP1012 | B15: Bob Johnson | C15: Sales | D15: Unknown | E15: 96418 | F15: 42092 | G15: 5 | H15: Male | I15: user106@example.com
... A32: EMP1029 | B32: Bob Johnson | C32: Marketing | D32: UK | E32: 92959 | F32: 42211 | G32: 5 | H32: Unknown | I32: user83@example.com
A33: EMP1030 | B33: Unknown | C33: Marketing | D33: Unknown | E33: 92259 | F33: Unknown | G33: 1 | H33: Unknown | I33: user109@example.com
A34: EMP1031 | B34: Eve Adams | C34: HR | D34: Germany | E34: 92299 | F34: 42225 | G34: 3 | H34: Male | I34: user143@example.com
A35: EMP1032 | B35: Sam Wilson | C35: HR | D35: Unknown | E35: 95586 | F35: 42232 | G35: 3 | H35: Other | I35: user190@example.com
A36: EMP1033 | B36: Chris Lee | C36: Unknown | D36: USA | E36: 95367 | F36: 42239 | G36: 2.9381443 | H36: Male | I36: user136@example.com
A37: EMP1034 | B37: John Doe | C37: Sales | D37: Australia | E37: 79549 | F37: 42246 | G37: 3 | H37: Unknown | I37: user198@example.com
A38: EMP1035 | B38: Alice Brown | C38: Unknown | D38: UK | E38: 54463 | F38: 42253 | G38: 4 | H38: Male | I38: Unknown
A39: EMP1036 | B39: Alice Brown | C39: IT | D39: USA | E39: 89781 | F39: 42260 | G39: 2.9263158 | H39: Female | I39: user31@example.com
A40: EMP1037 | B40: Alice Brown | C40: HR | D40: Unknown | E40: 64796 | F40: 42267 | G40: 2.9263158 | H40: Other | I40: user98@example.com
A41: EMP1038 | B41: John Doe | C41: Marketing | D41: UK | E41: 52093 | F41: 42274 | G41: 5 | H41: Unknown | I41: user154@example.com
A42: EMP1039 | B42: Chris Lee | C42: HR | D42: UK | E42: 48224 | F42: 42281 | G42: 3 | H42: Unknown | I42: user42@example.com
A43: EMP1040 | B43: Bob Johnson | C43: Finance | D43: UK | E43: 64268.635 | F43: Unknown | G43: 4 | H43: Female | I43: user89@example.com
A44: EMP1041 | B44: Alice Brown | C44: IT | D44: Germany | E44: 33956 | F44: 42295 | G44: 2.8913043 | H44: Unknown | I44: user47@example.com
A45: EMP1042 | B45: Bob Johnson | C45: Unknown | D45: Australia | E45: 64913 | F45: 42302 | G45: 1 | H45: Female | I45: user175@example.com
A46: EMP1043 | B46: Alice Brown | C46: Marketing | D46: Australia | E46: 35326 | F46: 42309 | G46: 2.9120879 | H46: Female | I46: user57@example.com
A47: EMP1044 | B47: Chris Lee | C47: Finance | D47: Unknown | E47: 81610 | F47: 42316 | G47: 1 | H47: Unknown | I47: user20@example.com
A48: EMP1045 | B48: Unknown | C48: HR | D48: Unknown | E48: 58962 | F48: 42323 | G48: 3 | H48: Other | I48: user106@example.com
A49: EMP1046 | B49: Chris Lee | C49: IT | D49: Germany | E49: 92701 | F49: 42330 | G49: 3 | H49: Other | I49: user199@example.com
A50: EMP1047 | B50: Chris Lee | C50: HR | D50: India | E50: 58245 | F50: 42337 | G50: 4 | H50: Unknown | I50: user43@example.com
A51: EMP1048 | B51: John Doe | C51: Finance | D51: Unknown | E51: 66513 | F51: 42344 | G51: 2 | H51: Other | I51: user24@example.com
A52: EMP1049 | B52: Eve Adams | C52: HR | D52: Germany | E52: 78720 | F52: 42351 | G52: 5 | H52: Female | I52: user89@example.com
A53: EMP1050 | B53: Chris Lee | C53: Unknown | D53: Unknown | E53: 30686 | F53: Unknown | G53: 2 | H53: Female | I53: user95@example.com
A54: EMP1051 | B54: Sam Wilson | C54: Sales | D54: India | E54: 39423 | F54: 42365 | G54: 5 | H54: Unknown | I54: user59@example.com
A55: EMP1052 | B55: Eve Adams | C55: Marketing | D55: Unknown | E55: 30280 | F55: 42372 | G55: 1 | H55: Unknown | I55: user152@example.com
A56: EMP1053 | B56: Eve Adams | C56: Finance | D56: UK | E56: 33352 | F56: 42379 | G56: 3 | H56: Female | I56: user200@example.com
...

Sheet  Summary satistics 
A1: DAY-3 Summary Satistics
A2: Employee ID | B2: Name | C2: Department | D2: Country | E2: Salary | F2: Date of Joining | G2: Performance Rating | H2: Gender | I2: Email
A3: EMP1000 | B3: Unknown | C3: Finance | D3: Unknown | E3: 66280.93 | F3: Unknown | G3: 2 | H3: Unknown | I3: Unknown | K3: Metric | L3: Salary | M3: Perfomance Rating
A4: EMP1001 | B4: Eve Adams | C4: HR | D4: Germany | E4: 54255 | F4: 42015 | G4: 1 | H4: Other | I4: user106@example.com
A5: EMP1002 | B5: Alice Brown | C5: Finance | D5: Germany | E5: 63184 | F5: 42022 | G5: 2 | H5: Unknown | I5: user176@example.com | K5: Total | L5: =SUM(Table14[Salary]) -> 9936329.3 | M5: =SUM(G3:G152) -> 432.06643
A6: EMP1003 | B6: John Doe | C6: Sales | D6: USA | E6: 94406 | F6: 42029 | G6: 1 | H6: Male | I6: user168@example.com
A7: EMP1004 | B7: Jane Smith | C7: Sales | D7: Germany | E7: 64120 | F7: 42036 | G7: 1 | H7: Male | I7: user49@example.com | K7: Average | L7: =AVERAGE(E3:E152) -> 66242.196 | M7: =AVERAGE(G3:G152) -> 2.8804429
A8: EMP1005 | B8: Alice Brown | C8: IT | D8: India | E8: 78421 | F8: 42043 | G8: 2 | H8: Female | I8: user24@example.com
A9: EMP1006 | B9: Sam Wilson | C9: Sales | D9: Unknown | E9: 67721 | F9: 42050 | G9: 2.9411765 | H9: Male | I9: user168@example.com | K9: Minimum | L9: =MIN(E3:E152) -> 30280 | M9: =MIN(G3:G152) -> 1
A10: EMP1007 | B10: Chris Lee | C10: Marketing | D10: Unknown | E10: 35364 | F10: 42057 | G10: 2 | H10: Other | I10: user26@example.com
A11: EMP1008 | B11: Alice Brown | C11: IT | D11: Germany | E11: 97881 | F11: 42064 | G11: 2.9491525 | H11: Female | I11: user25@example.com | K11: Maximum | L11: =MAX(E3:E152) -> 99621 | M11: =MAX(G3:G152) -> 5
A12: EMP1009 | B12: Chris Lee | C12: HR | D12: UK | E12: 91846 | F12: 42071 | G12: 2.9491525 | H12: Male | I12: user153@example.com
A13: EMP1010 | B13: Sam Wilson | C13: Finance | D13: UK | E13: 64247 | F13: 42078 | G13: 1 | H13: Female | I13: user18@example.com | K13: Count | L13: =COUNT(E3:E152) -> 150 | M13: =COUNT(G3:G152) -> 150
A14: EMP1011 | B14: Sam Wilson | C14: IT | D14: USA | E14: 91180 | F14: 42085 | G14: 5 | H14: Male | I14: user1@example.com
A15: EMP1012 | B15: Bob Johnson | C15: Sales | D15: Unknown | E15: 96418 | F15: 42092 | G15: 5 | H15: Male | I15: user106@example.com
A16: EMP1013 | B16: Sam Wilson | C16: Unknown | D16: India | E16: 62158 | F16: 42099 | G16: 4 | H16: Unknown | I16: user180@example.com
A17: EMP1014 | B17: Jane Smith | C17: HR | D17: Unknown | E17: 59894 | F17: 42106 | G17: 2 | H17: Male | I17: user184@example.com
A18: EMP1015 | B18: Unknown | C18: IT | D18: India | E18: 92443 | F18: 42113 | G18: 3 | H18: Other | I18: user3@example.com
A19: EMP1016 | B19: Bob Johnson | C19: Unknown | D19: Germany | E19: 90271 | F19: 42120 | G19: 2.9285714 | H19: Unknown | I19: user64@example.com
A20: EMP1017 | B20: Jane Smith | C20: Finance | D20: Australia | E20: 41341 | F20: 42127 | G20: 1 | H20: Other | I20: user38@example.com
A21: EMP1018 | B21: Alice Brown | C21: Finance | D21: UK | E21: 73602 | F21: 42134 | G21: 2.9459459 | H21: Unknown | I21: user96@example.com
A22: EMP1019 | B22: Eve Adams | C22: Unknown | D22: India | E22: 67531 | F22: 42141 | G22: 5 | H22: Female | I22: user151@example.com
A23: EMP1020 | B23: Jane Smith | C23: HR | D23: USA | E23: 65248.854 | F23: 42148 | G23: 2 | H23: Other | I23: user200@example.com
A24: EMP1021 | B24: Jane Smith | C24: HR | D24: Unknown | E24: 98922 | F24: 42155 | G24: 4 | H24: Unknown | I24: user77@example.com
A25: EMP1022 | B25: Eve Adams | C25: Finance | D25: India | E25: 38333 | F25: 42162 | G25: 5 | H25: Unknown | I25: user128@example.com
... A32: EMP1029 | B32: Bob Johnson | C32: Marketing | D32: UK | E32: 92959 | F32: 42211 | G32: 5 | H32: Unknown | I32: user83@example.com
A33: EMP1030 | B33: Unknown | C33: Marketing | D33: Unknown | E33: 92259 | F33: Unknown | G33: 1 | H33: Unknown | I33: user109@example.com
A34: EMP1031 | B34: Eve Adams | C34: HR | D34: Germany | E34: 92299 | F34: 42225 | G34: 3 | H34: Male | I34: user143@example.com
A35: EMP1032 | B35: Sam Wilson | C35: HR | D35: Unknown | E35: 95586 | F35: 42232 | G35: 3 | H35: Other | I35: user190@example.com
A36: EMP1033 | B36: Chris Lee | C36: Unknown | D36: USA | E36: 95367 | F36: 42239 | G36: 2.9381443 | H36: Male | I36: user136@example.com
A37: EMP1034 | B37: John Doe | C37: Sales | D37: Australia | E37: 79549 | F37: 42246 | G37: 3 | H37: Unknown | I37: user198@example.com
A38: EMP1035 | B38: Alice Brown | C38: Unknown | D38: UK | E38: 54463 | F38: 42253 | G38: 4 | H38: Male | I38: Unknown
A39: EMP1036 | B39: Alice Brown | C39: IT | D39: USA | E39: 89781 | F39: 42260 | G39: 2.9263158 | H39: Female | I39: user31@example.com
A40: EMP1037 | B40: Alice Brown | C40: HR | D40: Unknown | E40: 64796 | F40: 42267 | G40: 2.9263158 | H40: Other | I40: user98@example.com
A41: EMP1038 | B41: John Doe | C41: Marketing | D41: UK | E41: 52093 | F41: 42274 | G41: 5 | H41: Unknown | I41: user154@example.com
A42: EMP1039 | B42: Chris Lee | C42: HR | D42: UK | E42: 48224 | F42: 42281 | G42: 3 | H42: Unknown | I42: user42@example.com
A43: EMP1040 | B43: Bob Johnson | C43: Finance | D43: UK | E43: 64268.635 | F43: Unknown | G43: 4 | H43: Female | I43: user89@example.com
A44: EMP1041 | B44: Alice Brown | C44: IT | D44: Germany | E44: 33956 | F44: 42295 | G44: 2.8913043 | H44: Unknown | I44: user47@example.com
A45: EMP1042 | B45: Bob Johnson | C45: Unknown | D45: Australia | E45: 64913 | F45: 42302 | G45: 1 | H45: Female | I45: user175@example.com
A46: EMP1043 | B46: Alice Brown | C46: Marketing | D46: Australia | E46: 35326 | F46: 42309 | G46: 2.9120879 | H46: Female | I46: user57@example.com
...

Sheet  Condition Formatting
A1: DAY-4 Condition Formatting
A2: Employee ID | B2: Name | C2: Department | D2: Country | E2: Salary | F2: Date of Joining | G2: Performance Rating | H2: Gender | I2: Email | J2: Salary Category
A3: EMP1000 | B3: Unknown | C3: Finance | D3: Unknown | E3: 66280.93 | F3: Unknown | G3: 2 | H3: Unknown | I3: Unknown | J3: =IF(E3>80000,"High Salary", "Normal") -> Normal
A4: EMP1001 | B4: Eve Adams | C4: HR | D4: Germany | E4: 54255 | F4: 42015 | G4: 1 | H4: Other | I4: user106@example.com | J4: =IF(E4>80000,"High Salary", "Normal") -> Normal | K4: Conditional Formulas
A5: EMP1002 | B5: Alice Brown | C5: Finance | D5: Germany | E5: 63184 | F5: 42022 | G5: 2 | H5: Unknown | I5: user176@example.com | J5: =IF(E5>80000,"High Salary", "Normal") -> Normal
A6: EMP1003 | B6: John Doe | C6: Sales | D6: USA | E6: 94406 | F6: 42029 | G6: 1 | H6: Male | I6: user168@example.com | J6: =IF(E6>80000,"High Salary", "Normal") -> High Salary
A7: EMP1004 | B7: Jane Smith | C7: Sales | D7: Germany | E7: 64120 | F7: 42036 | G7: 1 | H7: Male | I7: user49@example.com | J7: =IF(E7>80000,"High Salary", "Normal") -> Normal | K7: Condition Name | L7: Description | M7: Formula Used | N7: Result
A8: EMP1005 | B8: Alice Brown | C8: IT | D8: India | E8: 78421 | F8: 42043 | G8: 2 | H8: Female | I8: user24@example.com | J8: =IF(E8>80000,"High Salary", "Normal") -> Normal
A9: EMP1006 | B9: Sam Wilson | C9: Sales | D9: Unknown | E9: 67721 | F9: 42050 | G9: 2.9411765 | H9: Male | I9: user168@example.com | J9: =IF(E9>80000,"High Salary", "Normal") -> Normal | K9: High Salary Count | L9: Count employees with salary above 70,000 | M9: COUNTIF | N9: =COUNTIF(E3:E152,">70000") -> 64
A10: EMP1007 | B10: Chris Lee | C10: Marketing | D10: Unknown | E10: 35364 | F10: 42057 | G10: 2 | H10: Other | I10: user26@example.com | J10: =IF(E10>80000,"High Salary", "Normal") -> Normal
A11: EMP1008 | B11: Alice Brown | C11: IT | D11: Germany | E11: 97881 | F11: 42064 | G11: 2.9491525 | H11: Female | I11: user25@example.com | J11: =IF(E11>80000,"High Salary", "Normal") -> High Salary | K11: Finance Salary Total | L11: Total salary of Finance employees | M11: SUMIF | N11: =SUMIF(C3:C152, "Finance",(E3:E152)) -> 1442640.6
A12: EMP1009 | B12: Chris Lee | C12: HR | D12: UK | E12: 91846 | F12: 42071 | G12: 2.9491525 | H12: Male | I12: user153@example.com | J12: =IF(E12>80000,"High Salary", "Normal") -> High Salary
A13: EMP1010 | B13: Sam Wilson | C13: Finance | D13: UK | E13: 64247 | F13: 42078 | G13: 1 | H13: Female | I13: user18@example.com | J13: =IF(E13>80000,"High Salary", "Normal") -> Normal | K13: Sales Avg Rating | L13: Average performance rating for Sales department | M13: AVERAGEIF | N13: =AVERAGEIF(C3:C152,"Sales",(G3:G152)) -> 2.7541478
A14: EMP1011 | B14: Sam Wilson | C14: IT | D14: USA | E14: 91180 | F14: 42085 | G14: 5 | H14: Male | I14: user1@example.com | J14: =IF(E14>80000,"High Salary", "Normal") -> High Salary
A15: EMP1012 | B15: Bob Johnson | C15: Sales | D15: Unknown | E15: 96418 | F15: 42092 | G15: 5 | H15: Male | I15: user106@example.com | J15: =IF(E15>80000,"High Salary", "Normal") -> High Salary
A16: EMP1013 | B16: Sam Wilson | C16: Unknown | D16: India | E16: 62158 | F16: 42099 | G16: 4 | H16: Unknown | I16: user180@example.com | J16: =IF(E16>80000,"High Salary", "Normal") -> Normal
A17: EMP1014 | B17: Jane Smith | C17: HR | D17: Unknown | E17: 59894 | F17: 42106 | G17: 2 | H17: Male | I17: user184@example.com | J17: =IF(E17>80000,"High Salary", "Normal") -> Normal
A18: EMP1015 | B18: Unknown | C18: IT | D18: India | E18: 92443 | F18: 42113 | G18: 3 | H18: Other | I18: user3@example.com | J18: =IF(E18>80000,"High Salary", "Normal") -> High Salary
A19: EMP1016 | B19: Bob Johnson | C19: Unknown | D19: Germany | E19: 90271 | F19: 42120 | G19: 2.9285714 | H19: Unknown | I19: user64@example.com | J19: =IF(E19>80000,"High Salary", "Normal") -> High Salary
A20: EMP1017 | B20: Jane Smith | C20: Finance | D20: Australia | E20: 41341 | F20: 42127 | G20: 1 | H20: Other | I20: user38@example.com | J20: =IF(E20>80000,"High Salary", "Normal") -> Normal
A21: EMP1018 | B21: Alice Brown | C21: Finance | D21: UK | E21: 73602 | F21: 42134 | G21: 2.9459459 | H21: Unknown | I21: user96@example.com | J21: =IF(E21>80000,"High Salary", "Normal") -> Normal
A22: EMP1019 | B22: Eve Adams | C22: Unknown | D22: India | E22: 67531 | F22: 42141 | G22: 5 | H22: Female | I22: user151@example.com | J22: =IF(E22>80000,"High Salary", "Normal") -> Normal
A23: EMP1020 | B23: Jane Smith | C23: HR | D23: USA | E23: 65248.854 | F23: 42148 | G23: 2 | H23: Other | I23: user200@example.com | J23: =IF(E23>80000,"High Salary", "Normal") -> Normal
A24: EMP1021 | B24: Jane Smith | C24: HR | D24: Unknown | E24: 98922 | F24: 42155 | G24: 4 | H24: Unknown | I24: user77@example.com | J24: =IF(E24>80000,"High Salary", "Normal") -> High Salary
A25: EMP1022 | B25: Eve Adams | C25: Finance | D25: India | E25: 38333 | F25: 42162 | G25: 5 | H25: Unknown | I25: user128@example.com | J25: =IF(E25>80000,"High Salary", "Normal") -> Normal
... A32: EMP1029 | B32: Bob Johnson | C32: Marketing | D32: UK | E32: 92959 | F32: 42211 | G32: 5 | H32: Unknown | I32: user83@example.com | J32: =IF(E32>80000,"High Salary", "Normal") -> High Salary
A33: EMP1030 | B33: Unknown | C33: Marketing | D33: Unknown | E33: 92259 | F33: Unknown | G33: 1 | H33: Unknown | I33: user109@example.com | J33: =IF(E33>80000,"High Salary", "Normal") -> High Salary
A34: EMP1031 | B34: Eve Adams | C34: HR | D34: Germany | E34: 92299 | F34: 42225 | G34: 3 | H34: Male | I34: user143@example.com | J34: =IF(E34>80000,"High Salary", "Normal") -> High Salary
A35: EMP1032 | B35: Sam Wilson | C35: HR | D35: Unknown | E35: 95586 | F35: 42232 | G35: 3 | H35: Other | I35: user190@example.com | J35: =IF(E35>80000,"High Salary", "Normal") -> High Salary
A36: EMP1033 | B36: Chris Lee | C36: Unknown | D36: USA | E36: 95367 | F36: 42239 | G36: 2.9381443 | H36: Male | I36: user136@example.com | J36: =IF(E36>80000,"High Salary", "Normal") -> High Salary
A37: EMP1034 | B37: John Doe | C37: Sales | D37: Australia | E37: 79549 | F37: 42246 | G37: 3 | H37: Unknown | I37: user198@example.com | J37: =IF(E37>80000,"High Salary", "Normal") -> Normal
A38: EMP1035 | B38: Alice Brown | C38: Unknown | D38: UK | E38: 54463 | F38: 42253 | G38: 4 | H38: Male | I38: Unknown | J38: =IF(E38>80000,"High Salary", "Normal") -> Normal
A39: EMP1036 | B39: Alice Brown | C39: IT | D39: USA | E39: 89781 | F39: 42260 | G39: 2.9263158 | H39: Female | I39: user31@example.com | J39: =IF(E39>80000,"High Salary", "Normal") -> High Salary
A40: EMP1037 | B40: Alice Brown | C40: HR | D40: Unknown | E40: 64796 | F40: 42267 | G40: 2.9263158 | H40: Other | I40: user98@example.com | J40: =IF(E40>80000,"High Salary", "Normal") -> Normal
A41: EMP1038 | B41: John Doe | C41: Marketing | D41: UK | E41: 52093 | F41: 42274 | G41: 5 | H41: Unknown | I41: user154@example.com | J41: =IF(E41>80000,"High Salary", "Normal") -> Normal
A42: EMP1039 | B42: Chris Lee | C42: HR | D42: UK | E42: 48224 | F42: 42281 | G42: 3 | H42: Unknown | I42: user42@example.com | J42: =IF(E42>80000,"High Salary", "Normal") -> Normal
A43: EMP1040 | B43: Bob Johnson | C43: Finance | D43: UK | E43: 64268.635 | F43: Unknown | G43: 4 | H43: Female | I43: user89@example.com | J43: =IF(E43>80000,"High Salary", "Normal") -> Normal
A44: EMP1041 | B44: Alice Brown | C44: IT | D44: Germany | E44: 33956 | F44: 42295 | G44: 2.8913043 | H44: Unknown | I44: user47@example.com | J44: =IF(E44>80000,"High Salary", "Normal") -> Normal
A45: EMP1042 | B45: Bob Johnson | C45: Unknown | D45: Australia | E45: 64913 | F45: 42302 | G45: 1 | H45: Female | I45: user175@example.com | J45: =IF(E45>80000,"High Salary", "Normal") -> Normal
A46: EMP1043 | B46: Alice Brown | C46: Marketing | D46: Australia | E46: 35326 | F46: 42309 | G46: 2.9120879 | H46: Female | I46: user57@example.com | J46: =IF(E46>80000,"High Salary", "Normal") -> Normal
...

Sheet Text  Cleanup
B1: DAY 5 – Text Cleaning with Excel Functions
A2: Employee ID | B2: Name | C2: Department | D2: Country | E2: Salary | F2: Date of Joining | G2: Performance Rating | H2: Gender | I2: Email | J2: Salary Category
A3: EMP1000 | B3: Unknown | C3: Finance | D3: Unknown | E3: 66280.93 | F3: Unknown | G3: 2 | H3: Unknown | I3: Unknown | J3: =IF(E3>80000,"High Salary", "Normal") -> Normal
A4: EMP1001 | B4: Eve Adams | C4: HR | D4: Germany | E4: 54255 | F4: 42015 | G4: 1 | H4: Other | I4: user106@example.com | J4: =IF(E4>80000,"High Salary", "Normal") -> Normal | L4: Column Name | M4: Description | N4: Formula Used | O4: Example
A5: EMP1002 | B5: Alice Brown | C5: Finance | D5: Germany | E5: 63184 | F5: 42022 | G5: 2 | H5: Unknown | I5: user176@example.com | J5: =IF(E5>80000,"High Salary", "Normal") -> Normal
A6: EMP1003 | B6: John Doe | C6: Sales | D6: USA | E6: 94406 | F6: 42029 | G6: 1 | H6: Male | I6: user168@example.com | J6: =IF(E6>80000,"High Salary", "Normal") -> High Salary | L6: Name | M6: Convert to proper case | N6: PROPER | O6: =PROPER(B8) -> Alice Brown
A7: EMP1004 | B7: Jane Smith | C7: Sales | D7: Germany | E7: 64120 | F7: 42036 | G7: 1 | H7: Male | I7: user49@example.com | J7: =IF(E7>80000,"High Salary", "Normal") -> Normal | L7: Department | M7: Convert to UPPERCASE | N7: UPPER() | O7: =UPPER(C12) -> HR
A8: EMP1005 | B8: Alice Brown | C8: IT | D8: India | E8: 78421 | F8: 42043 | G8: 2 | H8: Female | I8: user24@example.com | J8: =IF(E8>80000,"High Salary", "Normal") -> Normal | L8: Country | M8: Convert to lowercase | N8: LOWER() | O8: =LOWER(D6) -> usa
A9: EMP1006 | B9: Sam Wilson | C9: Sales | D9: Unknown | E9: 67721 | F9: 42050 | G9: 2.9411765 | H9: Male | I9: user168@example.com | J9: =IF(E9>80000,"High Salary", "Normal") -> Normal | L9: Email | M9: Extract left part of text | N9: LEFT() | O9: =LEFT(I4,"7") -> user106
A10: EMP1007 | B10: Chris Lee | C10: Marketing | D10: Unknown | E10: 35364 | F10: 42057 | G10: 2 | H10: Other | I10: user26@example.com | J10: =IF(E10>80000,"High Salary", "Normal") -> Normal | L10: Name | M10: Extract right part of text | N10: RIGHT() | O10: =RIGHT(B7,"5") -> Smith
A11: EMP1008 | B11: Alice Brown | C11: IT | D11: Germany | E11: 97881 | F11: 42064 | G11: 2.9491525 | H11: Female | I11: user25@example.com | J11: =IF(E11>80000,"High Salary", "Normal") -> High Salary | L11: Email | M11: Extract middle characters | N11: MID() | O11: =MID(I13,7,1) -> @
A12: EMP1009 | B12: Chris Lee | C12: HR | D12: UK | E12: 91846 | F12: 42071 | G12: 2.9491525 | H12: Male | I12: user153@example.com | J12: =IF(E12>80000,"High Salary", "Normal") -> High Salary | L12: Name | M12: Remove extra spaces | N12: TRIM() | O12: =TRIM(B13) -> Sam Wilson
A13: EMP1010 | B13: Sam Wilson | C13: Finance | D13: UK | E13: 64247 | F13: 42078 | G13: 1 | H13: Female | I13: user18@example.com | J13: =IF(E13>80000,"High Salary", "Normal") -> Normal
A14: EMP1011 | B14: Sam Wilson | C14: IT | D14: USA | E14: 91180 | F14: 42085 | G14: 5 | H14: Male | I14: user1@example.com | J14: =IF(E14>80000,"High Salary", "Normal") -> High Salary
A15: EMP1012 | B15: Bob Johnson | C15: Sales | D15: Unknown | E15: 96418 | F15: 42092 | G15: 5 | H15: Male | I15: user106@example.com | J15: =IF(E15>80000,"High Salary", "Normal") -> High Salary
A16: EMP1013 | B16: Sam Wilson | C16: Unknown | D16: India | E16: 62158 | F16: 42099 | G16: 4 | H16: Unknown | I16: user180@example.com | J16: =IF(E16>80000,"High Salary", "Normal") -> Normal
A17: EMP1014 | B17: Jane Smith | C17: HR | D17: Unknown | E17: 59894 | F17: 42106 | G17: 2 | H17: Male | I17: user184@example.com | J17: =IF(E17>80000,"High Salary", "Normal") -> Normal
A18: EMP1015 | B18: Unknown | C18: IT | D18: India | E18: 92443 | F18: 42113 | G18: 3 | H18: Other | I18: user3@example.com | J18: =IF(E18>80000,"High Salary", "Normal") -> High Salary
A19: EMP1016 | B19: Bob Johnson | C19: Unknown | D19: Germany | E19: 90271 | F19: 42120 | G19: 2.9285714 | H19: Unknown | I19: user64@example.com | J19: =IF(E19>80000,"High Salary", "Normal") -> High Salary
A20: EMP1017 | B20: Jane Smith | C20: Finance | D20: Australia | E20: 41341 | F20: 42127 | G20: 1 | H20: Other | I20: user38@example.com | J20: =IF(E20>80000,"High Salary", "Normal") -> Normal
A21: EMP1018 | B21: Alice Brown | C21: Finance | D21: UK | E21: 73602 | F21: 42134 | G21: 2.9459459 | H21: Unknown | I21: user96@example.com | J21: =IF(E21>80000,"High Salary", "Normal") -> Normal
A22: EMP1019 | B22: Eve Adams | C22: Unknown | D22: India | E22: 67531 | F22: 42141 | G22: 5 | H22: Female | I22: user151@example.com | J22: =IF(E22>80000,"High Salary", "Normal") -> Normal
A23: EMP1020 | B23: Jane Smith | C23: HR | D23: USA | E23: 65248.854 | F23: 42148 | G23: 2 | H23: Other | I23: user200@example.com | J23: =IF(E23>80000,"High Salary", "Normal") -> Normal
A24: EMP1021 | B24: Jane Smith | C24: HR | D24: Unknown | E24: 98922 | F24: 42155 | G24: 4 | H24: Unknown | I24: user77@example.com | J24: =IF(E24>80000,"High Salary", "Normal") -> High Salary
... A32: EMP1029 | B32: Bob Johnson | C32: Marketing | D32: UK | E32: 92959 | F32: 42211 | G32: 5 | H32: Unknown | I32: user83@example.com | J32: =IF(E32>80000,"High Salary", "Normal") -> High Salary
A33: EMP1030 | B33: Unknown | C33: Marketing | D33: Unknown | E33: 92259 | F33: Unknown | G33: 1 | H33: Unknown | I33: user109@example.com | J33: =IF(E33>80000,"High Salary", "Normal") -> High Salary
A34: EMP1031 | B34: Eve Adams | C34: HR | D34: Germany | E34: 92299 | F34: 42225 | G34: 3 | H34: Male | I34: user143@example.com | J34: =IF(E34>80000,"High Salary", "Normal") -> High Salary
A35: EMP1032 | B35: Sam Wilson | C35: HR | D35: Unknown | E35: 95586 | F35: 42232 | G35: 3 | H35: Other | I35: user190@example.com | J35: =IF(E35>80000,"High Salary", "Normal") -> High Salary
A36: EMP1033 | B36: Chris Lee | C36: Unknown | D36: USA | E36: 95367 | F36: 42239 | G36: 2.9381443 | H36: Male | I36: user136@example.com | J36: =IF(E36>80000,"High Salary", "Normal") -> High Salary
A37: EMP1034 | B37: John Doe | C37: Sales | D37: Australia | E37: 79549 | F37: 42246 | G37: 3 | H37: Unknown | I37: user198@example.com | J37: =IF(E37>80000,"High Salary", "Normal") -> Normal
A38: EMP1035 | B38: Alice Brown | C38: Unknown | D38: UK | E38: 54463 | F38: 42253 | G38: 4 | H38: Male | I38: Unknown | J38: =IF(E38>80000,"High Salary", "Normal") -> Normal
A39: EMP1036 | B39: Alice Brown | C39: IT | D39: USA | E39: 89781 | F39: 42260 | G39: 2.9263158 | H39: Female | I39: user31@example.com | J39: =IF(E39>80000,"High Salary", "Normal") -> High Salary
A40: EMP1037 | B40: Alice Brown | C40: HR | D40: Unknown | E40: 64796 | F40: 42267 | G40: 2.9263158 | H40: Other | I40: user98@example.com | J40: =IF(E40>80000,"High Salary", "Normal") -> Normal
A41: EMP1038 | B41: John Doe | C41: Marketing | D41: UK | E41: 52093 | F41: 42274 | G41: 5 | H41: Unknown | I41: user154@example.com | J41: =IF(E41>80000,"High Salary", "Normal") -> Normal
A42: EMP1039 | B42: Chris Lee | C42: HR | D42: UK | E42: 48224 | F42: 42281 | G42: 3 | H42: Unknown | I42: user42@example.com | J42: =IF(E42>80000,"High Salary", "Normal") -> Normal
A43: EMP1040 | B43: Bob Johnson | C43: Finance | D43: UK | E43: 64268.635 | F43: Unknown | G43: 4 | H43: Female | I43: user89@example.com | J43: =IF(E43>80000,"High Salary", "Normal") -> Normal
A44: EMP1041 | B44: Alice Brown | C44: IT | D44: Germany | E44: 33956 | F44: 42295 | G44: 2.8913043 | H44: Unknown | I44: user47@example.com | J44: =IF(E44>80000,"High Salary", "Normal") -> Normal
A45: EMP1042 | B45: Bob Johnson | C45: Unknown | D45: Australia | E45: 64913 | F45: 42302 | G45: 1 | H45: Female | I45: user175@example.com | J45: =IF(E45>80000,"High Salary", "Normal") -> Normal
A46: EMP1043 | B46: Alice Brown | C46: Marketing | D46: Australia | E46: 35326 | F46: 42309 | G46: 2.9120879 | H46: Female | I46: user57@example.com | J46: =IF(E46>80000,"High Salary", "Normal") -> Normal
A47: EMP1044 | B47: Chris Lee | C47: Finance | D47: Unknown | E47: 81610 | F47: 42316 | G47: 1 | H47: Unknown | I47: user20@example.com | J47: =IF(E47>80000,"High Salary", "Normal") -> High Salary
...

Sheet Finding Duplicates
A1: DAY-6 Finding and Removing Duplicates
A2: Employee ID | B2: Name | C2: Department | D2: Country | E2: Salary | F2: Date of Joining | G2: Performance Rating | H2: Gender | I2: Email
A3: EMP1000 | B3: Unknown | C3: Finance | D3: Unknown | E3: 66280.93 | F3: Unknown | G3: 2 | H3: Unknown | I3: Unknown
A4: EMP1001 | B4: Eve Adams | C4: HR | D4: Germany | E4: 54255 | F4: 42015 | G4: 1 | H4: Other | I4: user106@example.com | N4: Check Performed | O4: Result
A5: EMP1002 | B5: Alice Brown | C5: Finance | D5: Germany | E5: 63184 | F5: 42022 | G5: 2 | H5: Unknown | I5: user176@example.com | N5: Duplicate Check Columns | O5: Employee ID, Email
A6: EMP1003 | B6: John Doe | C6: Sales | D6: USA | E6: 94406 | F6: 42029 | G6: 1 | H6: Male | I6: user168@example.com | N6: Duplicate Values Found | O6: 0 duplicates
A7: EMP1004 | B7: Jane Smith | C7: Sales | D7: Germany | E7: 64120 | F7: 42036 | G7: 1 | H7: Male | I7: user49@example.com | N7: Total Records Before Cleaning | O7: 151 rows (example if this is your count)
A8: EMP1005 | B8: Alice Brown | C8: IT | D8: India | E8: 78421 | F8: 42043 | G8: 2 | H8: Female | I8: user24@example.com | N8: Total Records After Cleaning | O8: 151 rows
A9: EMP1006 | B9: Sam Wilson | C9: Sales | D9: Unknown | E9: 67721 | F9: 42050 | G9: 2.9411765 | H9: Male | I9: user168@example.com | N9: Notes | O9: No duplicates found. Data is unique and ready for next step.
A10: EMP1007 | B10: Chris Lee | C10: Marketing | D10: Unknown | E10: 35364 | F10: 42057 | G10: 2 | H10: Other | I10: user26@example.com
A11: EMP1008 | B11: Alice Brown | C11: IT | D11: Germany | E11: 97881 | F11: 42064 | G11: 2.9491525 | H11: Female | I11: user25@example.com
A12: EMP1009 | B12: Chris Lee | C12: HR | D12: UK | E12: 91846 | F12: 42071 | G12: 2.9491525 | H12: Male | I12: user153@example.com
A13: EMP1010 | B13: Sam Wilson | C13: Finance | D13: UK | E13: 64247 | F13: 42078 | G13: 1 | H13: Female | I13: user18@example.com
A14: EMP1011 | B14: Sam Wilson | C14: IT | D14: USA | E14: 91180 | F14: 42085 | G14: 5 | H14: Male | I14: user1@example.com
A15: EMP1012 | B15: Bob Johnson | C15: Sales | D15: Unknown | E15: 96418 | F15: 42092 | G15: 5 | H15: Male | I15: user106@example.com
A16: EMP1013 | B16: Sam Wilson | C16: Unknown | D16: India | E16: 62158 | F16: 42099 | G16: 4 | H16: Unknown | I16: user180@example.com
A17: EMP1014 | B17: Jane Smith | C17: HR | D17: Unknown | E17: 59894 | F17: 42106 | G17: 2 | H17: Male | I17: user184@example.com
A18: EMP1015 | B18: Unknown | C18: IT | D18: India | E18: 92443 | F18: 42113 | G18: 3 | H18: Other | I18: user3@example.com
A19: EMP1016 | B19: Bob Johnson | C19: Unknown | D19: Germany | E19: 90271 | F19: 42120 | G19: 2.9285714 | H19: Unknown | I19: user64@example.com
A20: EMP1017 | B20: Jane Smith | C20: Finance | D20: Australia | E20: 41341 | F20: 42127 | G20: 1 | H20: Other | I20: user38@example.com
A21: EMP1018 | B21: Alice Brown | C21: Finance | D21: UK | E21: 73602 | F21: 42134 | G21: 2.9459459 | H21: Unknown | I21: user96@example.com
... A32: EMP1029 | B32: Bob Johnson | C32: Marketing | D32: UK | E32: 92959 | F32: 42211 | G32: 5 | H32: Unknown | I32: user83@example.com
A33: EMP1030 | B33: Unknown | C33: Marketing | D33: Unknown | E33: 92259 | F33: Unknown | G33: 1 | H33: Unknown | I33: user109@example.com
A34: EMP1031 | B34: Eve Adams | C34: HR | D34: Germany | E34: 92299 | F34: 42225 | G34: 3 | H34: Male | I34: user143@example.com
A35: EMP1032 | B35: Sam Wilson | C35: HR | D35: Unknown | E35: 95586 | F35: 42232 | G35: 3 | H35: Other | I35: user190@example.com
A36: EMP1033 | B36: Chris Lee | C36: Unknown | D36: USA | E36: 95367 | F36: 42239 | G36: 2.9381443 | H36: Male | I36: user136@example.com
A37: EMP1034 | B37: John Doe | C37: Sales | D37: Australia | E37: 79549 | F37: 42246 | G37: 3 | H37: Unknown | I37: user198@example.com
A38: EMP1035 | B38: Alice Brown | C38: Unknown | D38: UK | E38: 54463 | F38: 42253 | G38: 4 | H38: Male | I38: Unknown
A39: EMP1036 | B39: Alice Brown | C39: IT | D39: USA | E39: 89781 | F39: 42260 | G39: 2.9263158 | H39: Female | I39: user31@example.com
A40: EMP1037 | B40: Alice Brown | C40: HR | D40: Unknown | E40: 64796 | F40: 42267 | G40: 2.9263158 | H40: Other | I40: user98@example.com
A41: EMP1038 | B41: John Doe | C41: Marketing | D41: UK | E41: 52093 | F41: 42274 | G41: 5 | H41: Unknown | I41: user154@example.com
A42: EMP1039 | B42: Chris Lee | C42: HR | D42: UK | E42: 48224 | F42: 42281 | G42: 3 | H42: Unknown | I42: user42@example.com
A43: EMP1040 | B43: Bob Johnson | C43: Finance | D43: UK | E43: 64268.635 | F43: Unknown | G43: 4 | H43: Female | I43: user89@example.com
A44: EMP1041 | B44: Alice Brown | C44: IT | D44: Germany | E44: 33956 | F44: 42295 | G44: 2.8913043 | H44: Unknown | I44: user47@example.com
A45: EMP1042 | B45: Bob Johnson | C45: Unknown | D45: Australia | E45: 64913 | F45: 42302 | G45: 1 | H45: Female | I45: user175@example.com
A46: EMP1043 | B46: Alice Brown | C46: Marketing | D46: Australia | E46: 35326 | F46: 42309 | G46: 2.9120879 | H46: Female | I46: user57@example.com
A47: EMP1044 | B47: Chris Lee | C47: Finance | D47: Unknown | E47: 81610 | F47: 42316 | G47: 1 | H47: Unknown | I47: user20@example.com
A48: EMP1045 | B48: Unknown | C48: HR | D48: Unknown | E48: 58962 | F48: 42323 | G48: 3 | H48: Other | I48: user106@example.com
A49: EMP1046 | B49: Chris Lee | C49: IT | D49: Germany | E49: 92701 | F49: 42330 | G49: 3 | H49: Other | I49: user199@example.com
A50: EMP1047 | B50: Chris Lee | C50: HR | D50: India | E50: 58245 | F50: 42337 | G50: 4 | H50: Unknown | I50: user43@example.com
...

Sheet  POWER QUERY 1
A1: DAY-7 Power Query
A2: Employee ID | B2: Name | C2: Department | D2: Country | E2: Salary | F2: Date of Joining | G2: Performance Rating | H2: Gender | I2: Email
A3: EMP1000 | B3: Unknown | C3: Finance | D3: Unknown | E3: 62745.947 | F3: Unknown | G3: 2 | H3: Unknown | I3: Unknown | K3: Day 7 – Power Query Cleaning Summary:
A4: EMP1001 | B4: Eve Adams | C4: HR | D4: Germany | E4: 54255 | F4: 42015 | G4: 1 | H4: Other | I4: user106@example.com | K4: ✓ Empty values replaced with Unknown labels
A5: EMP1002 | B5: Alice Brown | C5: Finance | D5: Germany | E5: 63184 | F5: 42022 | G5: 2 | H5: Unknown | I5: user176@example.com | K5: ✓ Trimmed and cleaned text columns
A6: EMP1003 | B6: John Doe | C6: Sales | D6: USA | E6: 94406 | F6: 42029 | G6: 1 | H6: Male | I6: user168@example.com | K6: ✓ Validated and corrected Email field
A7: EMP1004 | B7: Jane Smith | C7: Sales | D7: Germany | E7: 64120 | F7: 42036 | G7: 1 | H7: Male | I7: user49@example.com | K7: ✓ Ensured correct data types for every column
A8: EMP1005 | B8: Alice Brown | C8: IT | D8: India | E8: 78421 | F8: 42043 | G8: 2 | H8: Female | I8: user24@example.com | K8: ✓ Data loaded back with Power Query for auto-refresh capability
A9: EMP1006 | B9: Sam Wilson | C9: Sales | D9: Unknown | E9: 67721 | F9: 42050 | G9: 2.872 | H9: Male | I9: user168@example.com
A10: EMP1007 | B10: Chris Lee | C10: Marketing | D10: Unknown | E10: 35364 | F10: 42057 | G10: 2 | H10: Other | I10: user26@example.com
A11: EMP1008 | B11: Alice Brown | C11: IT | D11: Germany | E11: 97881 | F11: 42064 | G11: 2.872 | H11: Female | I11: user25@example.com
A12: EMP1009 | B12: Chris Lee | C12: HR | D12: UK | E12: 91846 | F12: 42071 | G12: 2.872 | H12: Male | I12: user153@example.com
A13: EMP1010 | B13: Sam Wilson | C13: Finance | D13: UK | E13: 64247 | F13: 42078 | G13: 1 | H13: Female | I13: user18@example.com
A14: EMP1011 | B14: Sam Wilson | C14: IT | D14: USA | E14: 91180 | F14: 42085 | G14: 5 | H14: Male | I14: user1@example.com
A15: EMP1012 | B15: Bob Johnson | C15: Sales | D15: Unknown | E15: 96418 | F15: 42092 | G15: 5 | H15: Male | I15: user106@example.com
A16: EMP1013 | B16: Sam Wilson | C16: Unknown | D16: India | E16: 62158 | F16: 42099 | G16: 4 | H16: Unknown | I16: user180@example.com
A17: EMP1014 | B17: Jane Smith | C17: HR | D17: Unknown | E17: 59894 | F17: 42106 | G17: 2 | H17: Male | I17: user184@example.com
A18: EMP1015 | B18: Unknown | C18: IT | D18: India | E18: 92443 | F18: 42113 | G18: 3 | H18: Other | I18: user3@example.com
A19: EMP1016 | B19: Bob Johnson | C19: Unknown | D19: Germany | E19: 90271 | F19: 42120 | G19: 2.872 | H19: Unknown | I19: user64@example.com
A20: EMP1017 | B20: Jane Smith | C20: Finance | D20: Australia | E20: 41341 | F20: 42127 | G20: 1 | H20: Other | I20: user38@example.com
... A32: EMP1029 | B32: Bob Johnson | C32: Marketing | D32: UK | E32: 92959 | F32: 42211 | G32: 5 | H32: Unknown | I32: user83@example.com
A33: EMP1030 | B33: Unknown | C33: Marketing | D33: Unknown | E33: 92259 | F33: Unknown | G33: 1 | H33: Unknown | I33: user109@example.com
A34: EMP1031 | B34: Eve Adams | C34: HR | D34: Germany | E34: 92299 | F34: 42225 | G34: 3 | H34: Male | I34: user143@example.com
A35: EMP1032 | B35: Sam Wilson | C35: HR | D35: Unknown | E35: 95586 | F35: 42232 | G35: 3 | H35: Other | I35: user190@example.com
A36: EMP1033 | B36: Chris Lee | C36: Unknown | D36: USA | E36: 95367 | F36: 42239 | G36: 2.872 | H36: Male | I36: user136@example.com
A37: EMP1034 | B37: John Doe | C37: Sales | D37: Australia | E37: 79549 | F37: 42246 | G37: 3 | H37: Unknown | I37: user198@example.com
A38: EMP1035 | B38: Alice Brown | C38: Unknown | D38: UK | E38: 54463 | F38: 42253 | G38: 4 | H38: Male | I38: Unknown
A39: EMP1036 | B39: Alice Brown | C39: IT | D39: USA | E39: 89781 | F39: 42260 | G39: 2.872 | H39: Female | I39: user31@example.com
A40: EMP1037 | B40: Alice Brown | C40: HR | D40: Unknown | E40: 64796 | F40: 42267 | G40: 2.872 | H40: Other | I40: user98@example.com
A41: EMP1038 | B41: John Doe | C41: Marketing | D41: UK | E41: 52093 | F41: 42274 | G41: 5 | H41: Unknown | I41: user154@example.com
A42: EMP1039 | B42: Chris Lee | C42: HR | D42: UK | E42: 48224 | F42: 42281 | G42: 3 | H42: Unknown | I42: user42@example.com
A43: EMP1040 | B43: Bob Johnson | C43: Finance | D43: UK | E43: 62745.947 | F43: Unknown | G43: 4 | H43: Female | I43: user89@example.com
A44: EMP1041 | B44: Alice Brown | C44: IT | D44: Germany | E44: 33956 | F44: 42295 | G44: 2.872 | H44: Unknown | I44: user47@example.com
A45: EMP1042 | B45: Bob Johnson | C45: Unknown | D45: Australia | E45: 64913 | F45: 42302 | G45: 1 | H45: Female | I45: user175@example.com
A46: EMP1043 | B46: Alice Brown | C46: Marketing | D46: Australia | E46: 35326 | F46: 42309 | G46: 2.872 | H46: Female | I46: user57@example.com
A47: EMP1044 | B47: Chris Lee | C47: Finance | D47: Unknown | E47: 81610 | F47: 42316 | G47: 1 | H47: Unknown | I47: user20@example.com
A48: EMP1045 | B48: Unknown | C48: HR | D48: Unknown | E48: 58962 | F48: 42323 | G48: 3 | H48: Other | I48: user106@example.com
A49: EMP1046 | B49: Chris Lee | C49: IT | D49: Germany | E49: 92701 | F49: 42330 | G49: 3 | H49: Other | I49: user199@example.com
A50: EMP1047 | B50: Chris Lee | C50: HR | D50: India | E50: 58245 | F50: 42337 | G50: 4 | H50: Unknown | I50: user43@example.com
A51: EMP1048 | B51: John Doe | C51: Finance | D51: Unknown | E51: 66513 | F51: 42344 | G51: 2 | H51: Other | I51: user24@example.com
...

Sheet Conditional Formatting
A1: DAY-8 Conditional Formatting (Data Quality Check)
A2: Employee ID | B2: Name | C2: Department | D2: Country | E2: Salary | F2: Date of Joining | G2: Performance Rating | H2: Gender | I2: Email | J2: Salary Category
A3: EMP1000 | B3: Unknown | C3: Finance | D3: Unknown | E3: 66280.93 | F3: Unknown | G3: 2 | H3: Unknown | I3: Unknown | J3: =IF(E3>80000,"High Salary", "Normal") -> Normal
A4: EMP1001 | B4: Eve Adams | C4: HR | D4: Germany | E4: 54255 | F4: 42015 | G4: 1 | H4: Other | I4: user106@example.com | J4: =IF(E4>80000,"High Salary", "Normal") -> Normal
A5: EMP1002 | B5: Alice Brown | C5: Finance | D5: Germany | E5: 63184 | F5: 42022 | G5: 2 | H5: Unknown | I5: user176@example.com | J5: =IF(E5>80000,"High Salary", "Normal") -> Normal
A6: EMP1003 | B6: John Doe | C6: Sales | D6: USA | E6: 94406 | F6: 42029 | G6: 1 | H6: Male | I6: user168@example.com | J6: =IF(E6>80000,"High Salary", "Normal") -> High Salary
A7: EMP1004 | B7: Jane Smith | C7: Sales | D7: Germany | E7: 64120 | F7: 42036 | G7: 1 | H7: Male | I7: user49@example.com | J7: =IF(E7>80000,"High Salary", "Normal") -> Normal
A8: EMP1005 | B8: Alice Brown | C8: IT | D8: India | E8: 78421 | F8: 42043 | G8: 2 | H8: Female | I8: user24@example.com | J8: =IF(E8>80000,"High Salary", "Normal") -> Normal
A9: EMP1006 | B9: Sam Wilson | C9: Sales | D9: Unknown | E9: 67721 | F9: 42050 | G9: 2.9411765 | H9: Male | I9: user168@example.com | J9: =IF(E9>80000,"High Salary", "Normal") -> Normal
A10: EMP1007 | B10: Chris Lee | C10: Marketing | D10: Unknown | E10: 35364 | F10: 42057 | G10: 2 | H10: Other | I10: user26@example.com | J10: =IF(E10>80000,"High Salary", "Normal") -> Normal
A11: EMP1008 | B11: Alice Brown | C11: IT | D11: Germany | E11: 97881 | F11: 42064 | G11: 2.9491525 | H11: Female | I11: user25@example.com | J11: =IF(E11>80000,"High Salary", "Normal") -> High Salary
A12: EMP1009 | B12: Chris Lee | C12: HR | D12: UK | E12: 91846 | F12: 42071 | G12: 2.9491525 | H12: Male | I12: user153@example.com | J12: =IF(E12>80000,"High Salary", "Normal") -> High Salary
A13: EMP1010 | B13: Sam Wilson | C13: Finance | D13: UK | E13: 64247 | F13: 42078 | G13: 1 | H13: Female | I13: user18@example.com | J13: =IF(E13>80000,"High Salary", "Normal") -> Normal
A14: EMP1011 | B14: Sam Wilson | C14: IT | D14: USA | E14: 91180 | F14: 42085 | G14: 5 | H14: Male | I14: user1@example.com | J14: =IF(E14>80000,"High Salary", "Normal") -> High Salary
A15: EMP1012 | B15: Bob Johnson | C15: Sales | D15: Unknown | E15: 96418 | F15: 42092 | G15: 5 | H15: Male | I15: user106@example.com | J15: =IF(E15>80000,"High Salary", "Normal") -> High Salary
... A32: EMP1029 | B32: Bob Johnson | C32: Marketing | D32: UK | E32: 92959 | F32: 42211 | G32: 5 | H32: Unknown | I32: user83@example.com | J32: =IF(E32>80000,"High Salary", "Normal") -> High Salary
A33: EMP1030 | B33: Unknown | C33: Marketing | D33: Unknown | E33: 92259 | F33: Unknown | G33: 1 | H33: Unknown | I33: user109@example.com | J33: =IF(E33>80000,"High Salary", "Normal") -> High Salary
A34: EMP1031 | B34: Eve Adams | C34: HR | D34: Germany | E34: 92299 | F34: 42225 | G34: 3 | H34: Male | I34: user143@example.com | J34: =IF(E34>80000,"High Salary", "Normal") -> High Salary
A35: EMP1032 | B35: Sam Wilson | C35: HR | D35: Unknown | E35: 95586 | F35: 42232 | G35: 3 | H35: Other | I35: user190@example.com | J35: =IF(E35>80000,"High Salary", "Normal") -> High Salary
A36: EMP1033 | B36: Chris Lee | C36: Unknown | D36: USA | E36: 95367 | F36: 42239 | G36: 2.9381443 | H36: Male | I36: user136@example.com | J36: =IF(E36>80000,"High Salary", "Normal") -> High Salary
A37: EMP1034 | B37: John Doe | C37: Sales | D37: Australia | E37: 79549 | F37: 42246 | G37: 3 | H37: Unknown | I37: user198@example.com | J37: =IF(E37>80000,"High Salary", "Normal") -> Normal
A38: EMP1035 | B38: Alice Brown | C38: Unknown | D38: UK | E38: 54463 | F38: 42253 | G38: 4 | H38: Male | I38: Unknown | J38: =IF(E38>80000,"High Salary", "Normal") -> Normal
A39: EMP1036 | B39: Alice Brown | C39: IT | D39: USA | E39: 89781 | F39: 42260 | G39: 2.9263158 | H39: Female | I39: user31@example.com | J39: =IF(E39>80000,"High Salary", "Normal") -> High Salary
A40: EMP1037 | B40: Alice Brown | C40: HR | D40: Unknown | E40: 64796 | F40: 42267 | G40: 2.9263158 | H40: Other | I40: user98@example.com | J40: =IF(E40>80000,"High Salary", "Normal") -> Normal
A41: EMP1038 | B41: John Doe | C41: Marketing | D41: UK | E41: 52093 | F41: 42274 | G41: 5 | H41: Unknown | I41: user154@example.com | J41: =IF(E41>80000,"High Salary", "Normal") -> Normal
A42: EMP1039 | B42: Chris Lee | C42: HR | D42: UK | E42: 48224 | F42: 42281 | G42: 3 | H42: Unknown | I42: user42@example.com | J42: =IF(E42>80000,"High Salary", "Normal") -> Normal
A43: EMP1040 | B43: Bob Johnson | C43: Finance | D43: UK | E43: 64268.635 | F43: Unknown | G43: 4 | H43: Female | I43: user89@example.com | J43: =IF(E43>80000,"High Salary", "Normal") -> Normal
A44: EMP1041 | B44: Alice Brown | C44: IT | D44: Germany | E44: 33956 | F44: 42295 | G44: 2.8913043 | H44: Unknown | I44: user47@example.com | J44: =IF(E44>80000,"High Salary", "Normal") -> Normal
A45: EMP1042 | B45: Bob Johnson | C45: Unknown | D45: Australia | E45: 64913 | F45: 42302 | G45: 1 | H45: Female | I45: user175@example.com | J45: =IF(E45>80000,"High Salary", "Normal") -> Normal
A46: EMP1043 | B46: Alice Brown | C46: Marketing | D46: Australia | E46: 35326 | F46: 42309 | G46: 2.9120879 | H46: Female | I46: user57@example.com | J46: =IF(E46>80000,"High Salary", "Normal") -> Normal
A47: EMP1044 | B47: Chris Lee | C47: Finance | D47: Unknown | E47: 81610 | F47: 42316 | G47: 1 | H47: Unknown | I47: user20@example.com | J47: =IF(E47>80000,"High Salary", "Normal") -> High Salary
A48: EMP1045 | B48: Unknown | C48: HR | D48: Unknown | E48: 58962 | F48: 42323 | G48: 3 | H48: Other | I48: user106@example.com | J48: =IF(E48>80000,"High Salary", "Normal") -> Normal
A49: EMP1046 | B49: Chris Lee | C49: IT | D49: Germany | E49: 92701 | F49: 42330 | G49: 3 | H49: Other | I49: user199@example.com | J49: =IF(E49>80000,"High Salary", "Normal") -> High Salary
A50: EMP1047 | B50: Chris Lee | C50: HR | D50: India | E50: 58245 | F50: 42337 | G50: 4 | H50: Unknown | I50: user43@example.com | J50: =IF(E50>80000,"High Salary", "Normal") -> Normal
A51: EMP1048 | B51: John Doe | C51: Finance | D51: Unknown | E51: 66513 | F51: 42344 | G51: 2 | H51: Other | I51: user24@example.com | J51: =IF(E51>80000,"High Salary", "Normal") -> Normal
A52: EMP1049 | B52: Eve Adams | C52: HR | D52: Germany | E52: 78720 | F52: 42351 | G52: 5 | H52: Female | I52: user89@example.com | J52: =IF(E52>80000,"High Salary", "Normal") -> Normal
A53: EMP1050 | B53: Chris Lee | C53: Unknown | D53: Unknown | E53: 30686 | F53: Unknown | G53: 2 | H53: Female | I53: user95@example.com | J53: =IF(E53>80000,"High Salary", "Normal") -> Normal
A54: EMP1051 | B54: Sam Wilson | C54: Sales | D54: India | E54: 39423 | F54: 42365 | G54: 5 | H54: Unknown | I54: user59@example.com | J54: =IF(E54>80000,"High Salary", "Normal") -> Normal
A55: EMP1052 | B55: Eve Adams | C55: Marketing | D55: Unknown | E55: 30280 | F55: 42372 | G55: 1 | H55: Unknown | I55: user152@example.com | J55: =IF(E55>80000,"High Salary", "Normal") -> Normal
A56: EMP1053 | B56: Eve Adams | C56: Finance | D56: UK | E56: 33352 | F56: 42379 | G56: 3 | H56: Female | I56: user200@example.com | J56: =IF(E56>80000,"High Salary", "Normal") -> Normal
...

Sheet Descriptive Statistics
A1: DAY-9 Descriptive Statistics
A2: Employee ID | B2: Name | C2: Department | D2: Country | E2: Salary | F2: Date of Joining | G2: Performance Rating | H2: Gender | I2: Email | J2: Salary Category
A3: EMP1000 | B3: Unknown | C3: Finance | D3: Unknown | E3: 66280.93 | F3: Unknown | G3: 2 | H3: Unknown | I3: Unknown | J3: =IF(E3>80000,"High Salary", "Normal") -> Normal
A4: EMP1001 | B4: Eve Adams | C4: HR | D4: Germany | E4: 54255 | F4: 42015 | G4: 1 | H4: Other | I4: user106@example.com | J4: =IF(E4>80000,"High Salary", "Normal") -> Normal
A5: EMP1002 | B5: Alice Brown | C5: Finance | D5: Germany | E5: 63184 | F5: 42022 | G5: 2 | H5: Unknown | I5: user176@example.com | J5: =IF(E5>80000,"High Salary", "Normal") -> Normal | L5: Descriptive statistics for salary
A6: EMP1003 | B6: John Doe | C6: Sales | D6: USA | E6: 94406 | F6: 42029 | G6: 1 | H6: Male | I6: user168@example.com | J6: =IF(E6>80000,"High Salary", "Normal") -> High Salary
A7: EMP1004 | B7: Jane Smith | C7: Sales | D7: Germany | E7: 64120 | F7: 42036 | G7: 1 | H7: Male | I7: user49@example.com | J7: =IF(E7>80000,"High Salary", "Normal") -> Normal | L7: Mean | M7: 66241.936
A8: EMP1005 | B8: Alice Brown | C8: IT | D8: India | E8: 78421 | F8: 42043 | G8: 2 | H8: Female | I8: user24@example.com | J8: =IF(E8>80000,"High Salary", "Normal") -> Normal | L8: Standard Error | M8: 1730.9413
A9: EMP1006 | B9: Sam Wilson | C9: Sales | D9: Unknown | E9: 67721 | F9: 42050 | G9: 2.9411765 | H9: Male | I9: user168@example.com | J9: =IF(E9>80000,"High Salary", "Normal") -> Normal | L9: Median | M9: 66079
A10: EMP1007 | B10: Chris Lee | C10: Marketing | D10: Unknown | E10: 35364 | F10: 42057 | G10: 2 | H10: Other | I10: user26@example.com | J10: =IF(E10>80000,"High Salary", "Normal") -> Normal | L10: Mode | M10: #N/A
A11: EMP1008 | B11: Alice Brown | C11: IT | D11: Germany | E11: 97881 | F11: 42064 | G11: 2.9491525 | H11: Female | I11: user25@example.com | J11: =IF(E11>80000,"High Salary", "Normal") -> High Salary | L11: Standard Deviation | M11: 21128.831
A12: EMP1009 | B12: Chris Lee | C12: HR | D12: UK | E12: 91846 | F12: 42071 | G12: 2.9491525 | H12: Male | I12: user153@example.com | J12: =IF(E12>80000,"High Salary", "Normal") -> High Salary | L12: Sample Variance | M12: 4.4642751e+08
A13: EMP1010 | B13: Sam Wilson | C13: Finance | D13: UK | E13: 64247 | F13: 42078 | G13: 1 | H13: Female | I13: user18@example.com | J13: =IF(E13>80000,"High Salary", "Normal") -> Normal | L13: Kurtosis | M13: -1.2055214
A14: EMP1011 | B14: Sam Wilson | C14: IT | D14: USA | E14: 91180 | F14: 42085 | G14: 5 | H14: Male | I14: user1@example.com | J14: =IF(E14>80000,"High Salary", "Normal") -> High Salary | L14: Skewness | M14: -0.11522987
A15: EMP1012 | B15: Bob Johnson | C15: Sales | D15: Unknown | E15: 96418 | F15: 42092 | G15: 5 | H15: Male | I15: user106@example.com | J15: =IF(E15>80000,"High Salary", "Normal") -> High Salary | L15: Range | M15: 69341
A16: EMP1013 | B16: Sam Wilson | C16: Unknown | D16: India | E16: 62158 | F16: 42099 | G16: 4 | H16: Unknown | I16: user180@example.com | J16: =IF(E16>80000,"High Salary", "Normal") -> Normal | L16: Minimum | M16: 30280
A17: EMP1014 | B17: Jane Smith | C17: HR | D17: Unknown | E17: 59894 | F17: 42106 | G17: 2 | H17: Male | I17: user184@example.com | J17: =IF(E17>80000,"High Salary", "Normal") -> Normal | L17: Maximum | M17: 99621
A18: EMP1015 | B18: Unknown | C18: IT | D18: India | E18: 92443 | F18: 42113 | G18: 3 | H18: Other | I18: user3@example.com | J18: =IF(E18>80000,"High Salary", "Normal") -> High Salary | L18: Sum | M18: 9870048.4
A19: EMP1016 | B19: Bob Johnson | C19: Unknown | D19: Germany | E19: 90271 | F19: 42120 | G19: 2.9285714 | H19: Unknown | I19: user64@example.com | J19: =IF(E19>80000,"High Salary", "Normal") -> High Salary | L19: Count | M19: 149
A20: EMP1017 | B20: Jane Smith | C20: Finance | D20: Australia | E20: 41341 | F20: 42127 | G20: 1 | H20: Other | I20: user38@example.com | J20: =IF(E20>80000,"High Salary", "Normal") -> Normal
A21: EMP1018 | B21: Alice Brown | C21: Finance | D21: UK | E21: 73602 | F21: 42134 | G21: 2.9459459 | H21: Unknown | I21: user96@example.com | J21: =IF(E21>80000,"High Salary", "Normal") -> Normal
A22: EMP1019 | B22: Eve Adams | C22: Unknown | D22: India | E22: 67531 | F22: 42141 | G22: 5 | H22: Female | I22: user151@example.com | J22: =IF(E22>80000,"High Salary", "Normal") -> Normal
A23: EMP1020 | B23: Jane Smith | C23: HR | D23: USA | E23: 65248.854 | F23: 42148 | G23: 2 | H23: Other | I23: user200@example.com | J23: =IF(E23>80000,"High Salary", "Normal") -> Normal
A24: EMP1021 | B24: Jane Smith | C24: HR | D24: Unknown | E24: 98922 | F24: 42155 | G24: 4 | H24: Unknown | I24: user77@example.com | J24: =IF(E24>80000,"High Salary", "Normal") -> High Salary
A25: EMP1022 | B25: Eve Adams | C25: Finance | D25: India | E25: 38333 | F25: 42162 | G25: 5 | H25: Unknown | I25: user128@example.com | J25: =IF(E25>80000,"High Salary", "Normal") -> Normal
A26: EMP1023 | B26: Alice Brown | C26: Marketing | D26: UK | E26: 36515 | F26: 42169 | G26: 3 | H26: Male | I26: user149@example.com | J26: =IF(E26>80000,"High Salary", "Normal") -> Normal
A27: EMP1024 | B27: Sam Wilson | C27: Finance | D27: Unknown | E27: 91005 | F27: 42176 | G27: 1 | H27: Other | I27: user122@example.com | J27: =IF(E27>80000,"High Salary", "Normal") -> High Salary
A28: EMP1025 | B28: Chris Lee | C28: Unknown | D28: Unknown | E28: 52272 | F28: 42183 | G28: 3 | H28: Unknown | I28: user41@example.com | J28: =IF(E28>80000,"High Salary", "Normal") -> Normal
A29: EMP1026 | B29: Eve Adams | C29: Sales | D29: Germany | E29: 76518 | F29: 42190 | G29: 2 | H29: Female | I29: user68@example.com | J29: =IF(E29>80000,"High Salary", "Normal") -> Normal
A30: EMP1027 | B30: Alice Brown | C30: IT | D30: UK | E30: 41448 | F30: 42197 | G30: 3 | H30: Other | I30: user103@example.com | J30: =IF(E30>80000,"High Salary", "Normal") -> Normal
A31: EMP1028 | B31: John Doe | C31: HR | D31: UK | E31: 49282 | F31: 42204 | G31: 2 | H31: Female | I31: user135@example.com | J31: =IF(E31>80000,"High Salary", "Normal") -> Normal
A32: EMP1029 | B32: Bob Johnson | C32: Marketing | D32: UK | E32: 92959 | F32: 42211 | G32: 5 | H32: Unknown | I32: user83@example.com | J32: =IF(E32>80000,"High Salary", "Normal") -> High Salary
A33: EMP1030 | B33: Unknown | C33: Marketing | D33: Unknown | E33: 92259 | F33: Unknown | G33: 1 | H33: Unknown | I33: user109@example.com | J33: =IF(E33>80000,"High Salary", "Normal") -> High Salary
A34: EMP1031 | B34: Eve Adams | C34: HR | D34: Germany | E34: 92299 | F34: 42225 | G34: 3 | H34: Male | I34: user143@example.com | J34: =IF(E34>80000,"High Salary", "Normal") -> High Salary
A35: EMP1032 | B35: Sam Wilson | C35: HR | D35: Unknown | E35: 95586 | F35: 42232 | G35: 3 | H35: Other | I35: user190@example.com | J35: =IF(E35>80000,"High Salary", "Normal") -> High Salary
A36: EMP1033 | B36: Chris Lee | C36: Unknown | D36: USA | E36: 95367 | F36: 42239 | G36: 2.9381443 | H36: Male | I36: user136@example.com | J36: =IF(E36>80000,"High Salary", "Normal") -> High Salary
A37: EMP1034 | B37: John Doe | C37: Sales | D37: Australia | E37: 79549 | F37: 42246 | G37: 3 | H37: Unknown | I37: user198@example.com | J37: =IF(E37>80000,"High Salary", "Normal") -> Normal
A38: EMP1035 | B38: Alice Brown | C38: Unknown | D38: UK | E38: 54463 | F38: 42253 | G38: 4 | H38: Male | I38: Unknown | J38: =IF(E38>80000,"High Salary", "Normal") -> Normal
A39: EMP1036 | B39: Alice Brown | C39: IT | D39: USA | E39: 89781 | F39: 42260 | G39: 2.9263158 | H39: Female | I39: user31@example.com | J39: =IF(E39>80000,"High Salary", "Normal") -> High Salary
A40: EMP1037 | B40: Alice Brown | C40: HR | D40: Unknown | E40: 64796 | F40: 42267 | G40: 2.9263158 | H40: Other | I40: user98@example.com | J40: =IF(E40>80000,"High Salary", "Normal") -> Normal
...

Sheet Filtering, Sorting & Exploring 
A1: DAY-10 Filtering, Sorting & Exploring Data
A2: Employee ID | B2: Name | C2: Department | D2: Country | E2: Salary | F2: Date of Joining | G2: Performance Rating | H2: Gender | I2: Email
A3: EMP1000 | B3: Unknown | C3: Finance | D3: Unknown | E3: 66280.93 | F3: Unknown | G3: 2 | H3: Unknown | I3: Unknown | K3: TOP 5 Highest Salary
A4: EMP1001 | B4: Eve Adams | C4: HR | D4: Germany | E4: 54255 | F4: 42015 | G4: 1 | H4: Other | I4: user106@example.com
A5: EMP1002 | B5: Alice Brown | C5: Finance | D5: Germany | E5: 63184 | F5: 42022 | G5: 2 | H5: Unknown | I5: user176@example.com | K5: Rank | L5: Employee ID | M5: Name | N5: Salary
A6: EMP1003 | B6: John Doe | C6: Sales | D6: USA | E6: 94406 | F6: 42029 | G6: 1 | H6: Male | I6: user168@example.com | K6: 1 | L6: EMP1083 | M6: Sam Wilson | N6: 99621
A7: EMP1004 | B7: Jane Smith | C7: Sales | D7: Germany | E7: 64120 | F7: 42036 | G7: 1 | H7: Male | I7: user49@example.com | K7: 2 | L7: EMP1021 | M7: Jane Smith | N7: 98922
A8: EMP1005 | B8: Alice Brown | C8: IT | D8: India | E8: 78421 | F8: 42043 | G8: 2 | H8: Female | I8: user24@example.com | K8: 3 | L8: EMP1149 | M8: Sam Wilson | N8: 98475
A9: EMP1006 | B9: Sam Wilson | C9: Sales | D9: Unknown | E9: 67721 | F9: 42050 | G9: 2.9411765 | H9: Male | I9: user168@example.com | K9: 4 | L9: EMP1062 | M9: Chris Lee | N9: 97981
A10: EMP1007 | B10: Chris Lee | C10: Marketing | D10: Unknown | E10: 35364 | F10: 42057 | G10: 2 | H10: Other | I10: user26@example.com | K10: 5 | L10: EMP1008 | M10: Alice Brown | N10: 97881
A11: EMP1008 | B11: Alice Brown | C11: IT | D11: Germany | E11: 97881 | F11: 42064 | G11: 2.9491525 | H11: Female | I11: user25@example.com
A12: EMP1009 | B12: Chris Lee | C12: HR | D12: UK | E12: 91846 | F12: 42071 | G12: 2.9491525 | H12: Male | I12: user153@example.com | K12: TOP 5 Performance Rating
